============================= test session starts ==============================
platform linux -- Python 3.11.10, pytest-8.4.0, pluggy-1.6.0 -- /home/runner/workspace/.pythonlibs/bin/python
cachedir: .pytest_cache
rootdir: /home/runner/workspace
configfile: pytest.ini
plugins: anyio-4.9.0, cov-6.2.1, mock-3.14.1, asyncio-1.0.0
asyncio: mode=Mode.STRICT, asyncio_default_fixture_loop_scope=None, asyncio_default_test_loop_scope=function
collecting ... collected 33 items / 2 errors

==================================== ERRORS ====================================
______________________ ERROR collecting tests/test_app.py ______________________
.pythonlibs/lib/python3.11/site-packages/_pytest/python.py:497: in importtestmodule
    mod = import_path(
.pythonlibs/lib/python3.11/site-packages/_pytest/pathlib.py:587: in import_path
    importlib.import_module(module_name)
/nix/store/clx0mcir7qw8zk36zbr4jra789g3knf6-python3-3.11.10/lib/python3.11/importlib/__init__.py:126: in import_module
    return _bootstrap._gcd_import(name[level:], package, level)
           ^^^^^^^^^^^^^^^^^^^^^^^^^^^^^^^^^^^^^^^^^^^^^^^^^^^^
<frozen importlib._bootstrap>:1204: in _gcd_import
    ???
<frozen importlib._bootstrap>:1176: in _find_and_load
    ???
<frozen importlib._bootstrap>:1147: in _find_and_load_unlocked
    ???
<frozen importlib._bootstrap>:690: in _load_unlocked
    ???
.pythonlibs/lib/python3.11/site-packages/_pytest/assertion/rewrite.py:177: in exec_module
    source_stat, co = _rewrite_test(fn, self.config)
                      ^^^^^^^^^^^^^^^^^^^^^^^^^^^^^^
.pythonlibs/lib/python3.11/site-packages/_pytest/assertion/rewrite.py:357: in _rewrite_test
    tree = ast.parse(source, filename=strfn)
           ^^^^^^^^^^^^^^^^^^^^^^^^^^^^^^^^^
/nix/store/clx0mcir7qw8zk36zbr4jra789g3knf6-python3-3.11.10/lib/python3.11/ast.py:50: in parse
    return compile(source, filename, mode, flags,
E     File "/home/runner/workspace/tests/test_app.py", line 29
E       assert response.status_code == 200tatus_code == 200
E                                        ^
E   SyntaxError: invalid decimal literal
_____________________ ERROR collecting tests/test_utils.py _____________________
.pythonlibs/lib/python3.11/site-packages/_pytest/python.py:497: in importtestmodule
    mod = import_path(
.pythonlibs/lib/python3.11/site-packages/_pytest/pathlib.py:587: in import_path
    importlib.import_module(module_name)
/nix/store/clx0mcir7qw8zk36zbr4jra789g3knf6-python3-3.11.10/lib/python3.11/importlib/__init__.py:126: in import_module
    return _bootstrap._gcd_import(name[level:], package, level)
           ^^^^^^^^^^^^^^^^^^^^^^^^^^^^^^^^^^^^^^^^^^^^^^^^^^^^
<frozen importlib._bootstrap>:1204: in _gcd_import
    ???
<frozen importlib._bootstrap>:1176: in _find_and_load
    ???
<frozen importlib._bootstrap>:1147: in _find_and_load_unlocked
    ???
<frozen importlib._bootstrap>:690: in _load_unlocked
    ???
.pythonlibs/lib/python3.11/site-packages/_pytest/assertion/rewrite.py:177: in exec_module
    source_stat, co = _rewrite_test(fn, self.config)
                      ^^^^^^^^^^^^^^^^^^^^^^^^^^^^^^
.pythonlibs/lib/python3.11/site-packages/_pytest/assertion/rewrite.py:357: in _rewrite_test
    tree = ast.parse(source, filename=strfn)
           ^^^^^^^^^^^^^^^^^^^^^^^^^^^^^^^^^
/nix/store/clx0mcir7qw8zk36zbr4jra789g3knf6-python3-3.11.10/lib/python3.11/ast.py:50: in parse
    return compile(source, filename, mode, flags,
E     File "/home/runner/workspace/tests/test_utils.py", line 86
E       ]
E       ^
E   SyntaxError: unmatched ']'
=============================== warnings summary ===============================
test_runner.py:18
  /home/runner/workspace/test_runner.py:18: PytestCollectionWarning: cannot collect test class 'TestRunner' because it has a __init__ constructor (from: test_runner.py)
    class TestRunner:

-- Docs: https://docs.pytest.org/en/stable/how-to/capture-warnings.html
=========================== short test summary info ============================
ERROR tests/test_app.py
ERROR tests/test_utils.py
!!!!!!!!!!!!!!!!!!! Interrupted: 2 errors during collection !!!!!!!!!!!!!!!!!!!!
========================= 1 warning, 2 errors in 1.54s =========================